Workbook

Sheet BD Parametros
C1: FLOTA TOTAL | D1: =COUNTA(O6:O284) -> 279 | E1: BASE DE DATOS AJUSTE DE PARÁMETROS
C2: AJUSTES REALIZADOS | D2: =COUNTIF(O6:O284,"SI") -> 147
C3: AJUSTES PENDIENTES | D3: =COUNTIF(O6:O296,"NO") -> 132
C4: AVANCE | D4: =D2/D1 -> 0.52688172 | R4: F.MTA.026 1-06/23
A5: TIPO ESTRUCTURA | B5: No. ECO | C5: VIN | D5: MARCA TRACTO | E5: MOTOR | F5: TIPO | G5: MODELO | H5: AÑO | I5: ESTRUCTURA | J5: TIPO2 | K5: TIPO3 | L5: ESTATUS | M5: REMOLQUE | N5: CLIENTE | O5: Ajuste | P5: FECHA DE AJUSTE | Q5: BASE DONDE SE REALIZÓ
A6: =Tabla2[[#This Row],[TIPO2]]&" "&Tabla2[[#This Row],[ESTRUCTURA]] -> QUINTA BAJA WS COTTRELL | B6: C01 | C6: 5KKHAEDV5LPLX8876 | D6: WESTERN STAR | E6: DETROIT DD15 | F6: DD15 | G6: 4900 | H6: 2023 | I6: COTTRELL | J6: QUINTA BAJA WS | K6: WS-COT | L6: CRECIMIENTO | M6: RE-C01 | N6: =VLOOKUP(Tabla2[[#This Row],[No. ECO]],Hoja1!A:D,2,FALSE) -> TY-APASEO- | O6: NO | T6: Etiquetas de fila | U6: Cuenta de TIPO ESTRUCTURA
A7: =Tabla2[[#This Row],[TIPO2]]&" "&Tabla2[[#This Row],[ESTRUCTURA]] -> QUINTA BAJA WS COTTRELL | B7: C02 | C7: 5KKHAEDVXMPMF1916 | D7: WESTERN STAR | E7: DETROIT DD13 | F7: DD13 | G7: 4900 | H7: 2023 | I7: COTTRELL | J7: QUINTA BAJA WS | K7: WS-COT | L7: CRECIMIENTO | M7: RE-C02 | N7: =VLOOKUP(Tabla2[[#This Row],[No. ECO]],Hoja1!A:D,2,FALSE) -> TY-APASEO- | O7: SI | P7: 45505 | Q7: Salinas | T7: QUINTA BAJA COTTRELL | U7: 46
A8: =Tabla2[[#This Row],[TIPO2]]&" "&Tabla2[[#This Row],[ESTRUCTURA]] -> QUINTA BAJA WS COTTRELL | B8: C03 | C8: 5KKHAEDV1MPMF1917 | D8: WESTERN STAR | E8: DETROIT DD13 | F8: DD13 | G8: 4900 | H8: 2023 | I8: COTTRELL | J8: QUINTA BAJA WS | K8: WS-COT | L8: CRECIMIENTO | M8: RE-C03 | N8: =VLOOKUP(Tabla2[[#This Row],[No. ECO]],Hoja1!A:D,2,FALSE) -> DT- | O8: SI | P8: 45521 | Q8: Salamanca | T8: SEMI FULL DOLLY COTTRELL | U8: 37
A9: =Tabla2[[#This Row],[TIPO2]]&" "&Tabla2[[#This Row],[ESTRUCTURA]] -> QUINTA BAJA WS COTTRELL | B9: C04 | C9: 5KKHAEDV3MPMF1918 | D9: WESTERN STAR | E9: DETROIT DD13 | F9: DD13 | G9: 4900 | H9: 2023 | I9: COTTRELL | J9: QUINTA BAJA WS | K9: WS-COT | L9: CRECIMIENTO | M9: RE-C04 | N9: =VLOOKUP(Tabla2[[#This Row],[No. ECO]],Hoja1!A:D,2,FALSE) -> DT- | O9: SI | P9: 45572 | Q9: Salinas | T9: QUINTA BAJA 2.0 COTTRELL | U9: 37
A10: =Tabla2[[#This Row],[TIPO2]]&" "&Tabla2[[#This Row],[ESTRUCTURA]] -> QUINTA BAJA WS COTTRELL | B10: C36 | C10: 5KKHAEDV3NPNP5807 | D10: WESTERN STAR | E10: DETROIT DD13 | F10: DD13 | G10: 4900 | H10: 2022 | I10: COTTRELL | J10: QUINTA BAJA WS | K10: WS-COT | L10: CRECIMIENTO | M10: RE-C36 | N10: =VLOOKUP(Tabla2[[#This Row],[No. ECO]],Hoja1!A:D,2,FALSE) -> TY-APASEO- | O10: NO | T10: QUINTA BAJA WS COTTRELL | U10: 23
A11: =Tabla2[[#This Row],[TIPO2]]&" "&Tabla2[[#This Row],[ESTRUCTURA]] -> QUINTA BAJA WS COTTRELL | B11: C37 | C11: 5KKHAEDV7NPNP5812 | D11: WESTERN STAR | E11: DETROIT DD13 | F11: DD13 | G11: 4900 | H11: 2022 | I11: COTTRELL | J11: QUINTA BAJA WS | K11: WS-COT | L11: CRECIMIENTO | M11: RE-C37 | N11: =VLOOKUP(Tabla2[[#This Row],[No. ECO]],Hoja1!A:D,2,FALSE) -> DT- | O11: SI | P11: 45521 | Q11: Salamanca | T11: QUINTA BAJA BOYDSTUN | U11: 22
A12: =Tabla2[[#This Row],[TIPO2]]&" "&Tabla2[[#This Row],[ESTRUCTURA]] -> QUINTA BAJA WS COTTRELL | B12: C38 | C12: 5KKHAEDV6NPNP5817 | D12: WESTERN STAR | E12: DETROIT DD13 | F12: DD13 | G12: 4900 | H12: 2022 | I12: COTTRELL | J12: QUINTA BAJA WS | K12: WS-COT | L12: CRECIMIENTO | M12: RE-C38 | N12: =VLOOKUP(Tabla2[[#This Row],[No. ECO]],Hoja1!A:D,2,FALSE) -> TY-APASEO- | O12: SI | P12: 45505 | Q12: Salinas | T12: FULL COTTRELL | U12: 20
A13: =Tabla2[[#This Row],[TIPO2]]&" "&Tabla2[[#This Row],[ESTRUCTURA]] -> QUINTA BAJA WS COTTRELL | B13: C39 | C13: 5KKHAEDVXNPNP5822 | D13: WESTERN STAR | E13: DETROIT DD13 | F13: DD13 | G13: 4900 | H13: 2022 | I13: COTTRELL | J13: QUINTA BAJA WS | K13: WS-COT | L13: CRECIMIENTO | M13: RE-C39 | N13: =VLOOKUP(Tabla2[[#This Row],[No. ECO]],Hoja1!A:D,2,FALSE) -> TY-APASEO- | O13: SI | P13: 45596 | Q13: Salinas | T13: C3 JAES | U13: 16
A14: =Tabla2[[#This Row],[TIPO2]]&" "&Tabla2[[#This Row],[ESTRUCTURA]] -> QUINTA BAJA WS COTTRELL | B14: C40 | C14: 5KKHAEDV5NPNP5825 | D14: WESTERN STAR | E14: DETROIT DD13 | F14: DD13 | G14: 4900 | H14: 2022 | I14: COTTRELL | J14: QUINTA BAJA WS | K14: WS-COT | L14: CRECIMIENTO | M14: RE-C40 | N14: =VLOOKUP(Tabla2[[#This Row],[No. ECO]],Hoja1!A:D,2,FALSE) -> DT- | O14: SI | P14: 45555 | Q14: Salinas | T14: FULL LOHR | U14: 9
A15: =Tabla2[[#This Row],[TIPO2]]&" "&Tabla2[[#This Row],[ESTRUCTURA]] -> QUINTA BAJA WS COTTRELL | B15: C41 | C15: 5KKHAEDV1NPNP5840 | D15: WESTERN STAR | E15: DETROIT DD13 | F15: DD13 | G15: 4900 | H15: 2022 | I15: COTTRELL | J15: QUINTA BAJA WS | K15: WS-COT | L15: CRECIMIENTO | M15: RE-C41 | N15: =VLOOKUP(Tabla2[[#This Row],[No. ECO]],Hoja1!A:D,2,FALSE) -> DT- | O15: SI | P15: 45521 | Q15: Salamanca | T15: QUINTA ALTA BOYDSTUN | U15: 5
A16: =Tabla2[[#This Row],[TIPO2]]&" "&Tabla2[[#This Row],[ESTRUCTURA]] -> QUINTA BAJA WS COTTRELL | B16: C42 | C16: 5KKHAEDV5NPNP5842 | D16: WESTERN STAR | E16: DETROIT DD13 | F16: DD13 | G16: 4900 | H16: 2022 | I16: COTTRELL | J16: QUINTA BAJA WS | K16: WS-COT | L16: CRECIMIENTO | M16: RE-C42 | N16: =VLOOKUP(Tabla2[[#This Row],[No. ECO]],Hoja1!A:D,2,FALSE) -> DT- | O16: NO | T16: Total general | U16: 215
A17: =Tabla2[[#This Row],[TIPO2]]&" "&Tabla2[[#This Row],[ESTRUCTURA]] -> QUINTA BAJA WS COTTRELL | B17: C43 | C17: 5KKHAEDV7NPNP5843 | D17: WESTERN STAR | E17: DETROIT DD13 | F17: DD13 | G17: 4900 | H17: 2022 | I17: COTTRELL | J17: QUINTA BAJA WS | K17: WS-COT | L17: CRECIMIENTO | M17: RE-C45 | N17: =VLOOKUP(Tabla2[[#This Row],[No. ECO]],Hoja1!A:D,2,FALSE) -> DT- | O17: NO
A18: =Tabla2[[#This Row],[TIPO2]]&" "&Tabla2[[#This Row],[ESTRUCTURA]] -> QUINTA BAJA WS COTTRELL | B18: C44 | C18: 5KKHAEDV3NPNP5872 | D18: WESTERN STAR | E18: DETROIT DD13 | F18: DD13 | G18: 4900 | H18: 2022 | I18: COTTRELL | J18: QUINTA BAJA WS | K18: WS-COT | L18: CRECIMIENTO | M18: RE-C44 | N18: =VLOOKUP(Tabla2[[#This Row],[No. ECO]],Hoja1!A:D,2,FALSE) -> DT- | O18: SI | P18: 45517 | Q18: Salamanca | T18: Etiquetas de fila | U18: Cuenta de MOTOR
A19: =Tabla2[[#This Row],[TIPO2]]&" "&Tabla2[[#This Row],[ESTRUCTURA]] -> QUINTA BAJA WS COTTRELL | B19: C45 | C19: 5KKHAEDV1NPNP5904 | D19: WESTERN STAR | E19: DETROIT DD13 | F19: DD13 | G19: 4900 | H19: 2022 | I19: COTTRELL | J19: QUINTA BAJA WS | K19: WS-COT | L19: CRECIMIENTO | M19: RE-C45 | N19: =VLOOKUP(Tabla2[[#This Row],[No. ECO]],Hoja1!A:D,2,FALSE) -> DT- | O19: SI | P19: 45586 | Q19: Salinas | T19: CUMMINS X15 | U19: 105
A20: =Tabla2[[#This Row],[TIPO2]]&" "&Tabla2[[#This Row],[ESTRUCTURA]] -> FULL COTTRELL | B20: TLEA-018 | C20: 3WKAD49X4GF863901 | D20: KENWORTH | E20: CUMMINS X15 | F20: X15 | G20: T660 | H20: 2023 | I20: COTTRELL | J20: FULL | K20: FULL | L20: RENOVACIÓN | M20: RE-018 | N20: =VLOOKUP(Tabla2[[#This Row],[No. ECO]],Hoja1!A:D,2,FALSE) -> TY-D- | O20: SI | P20: 45523 | Q20: Salamanca | T20: PACCAR MX-13 | U20: 53
A21: =Tabla2[[#This Row],[TIPO2]]&" "&Tabla2[[#This Row],[ESTRUCTURA]] -> QUINTA BAJA COTTRELL | B21: TLEA-021 | C21: 3BKZL40X0RF538110 | D21: KENWORTH | E21: CUMMINS X15 | F21: X15 | G21: T880 | H21: 2024 | I21: COTTRELL | J21: QUINTA BAJA | K21: QB | L21: RENOVACIÓN | M21: RE-021 | N21: =VLOOKUP(Tabla2[[#This Row],[No. ECO]],Hoja1!A:D,2,FALSE) -> GM- | O21: NO | T21: DETROIT DD13 | U21: 44
A22: =Tabla2[[#This Row],[TIPO2]]&" "&Tabla2[[#This Row],[ESTRUCTURA]] -> QUINTA BAJA COTTRELL | B22: TLEA-025 | C22: 3BKZL40XXPF536264 | D22: KENWORTH | E22: CUMMINS X15 | F22: X15 | G22: T660 | H22: 2023 | I22: COTTRELL | J22: QUINTA BAJA | K22: QB | L22: RENOVACIÓN | M22: RE-025 | N22: =VLOOKUP(Tabla2[[#This Row],[No. ECO]],Hoja1!A:D,2,FALSE) -> GM- | O22: SI | P22: 45610 | Q22: Salinas | T22: CUMMINS EPA 04 | U22: 10
A23: =Tabla2[[#This Row],[TIPO2]]&" "&Tabla2[[#This Row],[ESTRUCTURA]] -> QUINTA BAJA COTTRELL | B23: TLEA-027 | C23: 3BKZL40X8PF536263 | D23: KENWORTH | E23: CUMMINS X15 | F23: X15 | G23: T880 | H23: 2023 | I23: COTTRELL | J23: QUINTA BAJA | K23: QB | L23: RENOVACIÓN | M23: RE-027 | N23: =VLOOKUP(Tabla2[[#This Row],[No. ECO]],Hoja1!A:D,2,FALSE) -> BMW- | O23: SI | P23: 45520 | Q23: Salamanca | T23: DETROIT DD15 | U23: 3
A24: =Tabla2[[#This Row],[TIPO2]]&" "&Tabla2[[#This Row],[ESTRUCTURA]] -> QUINTA BAJA COTTRELL | B24: TLEA-028 | C24: 3BKZL40X5PF536270 | D24: KENWORTH | E24: CUMMINS X15 | F24: X15 | G24: T880 | H24: 2023 | I24: COTTRELL | J24: QUINTA BAJA | K24: QB | L24: RENOVACIÓN | M24: RE-028 | N24: =VLOOKUP(Tabla2[[#This Row],[No. ECO]],Hoja1!A:D,2,FALSE) -> GM- | O24: SI | P24: 45609 | Q24: Salinas | T24: Total general | U24: 215
A25: =Tabla2[[#This Row],[TIPO2]]&" "&Tabla2[[#This Row],[ESTRUCTURA]] -> QUINTA BAJA COTTRELL | B25: TLEA-030 | C25: 3BKZL40X3PF536266 | D25: KENWORTH | E25: CUMMINS X15 | F25: X15 | G25: T880 | H25: 2023 | I25: COTTRELL | J25: QUINTA BAJA | K25: QB | L25: RENOVACIÓN | M25: RE-030 | N25: =VLOOKUP(Tabla2[[#This Row],[No. ECO]],Hoja1!A:D,2,FALSE) -> GM- | O25: NO
A26: =Tabla2[[#This Row],[TIPO2]]&" "&Tabla2[[#This Row],[ESTRUCTURA]] -> QUINTA BAJA COTTRELL | B26: TLEA-031 | C26: 3BKZL40X5PF536267 | D26: KENWORTH | E26: CUMMINS X15 | F26: X15 | G26: T880 | H26: 2023 | I26: COTTRELL | J26: QUINTA BAJA | K26: QB | L26: RENOVACIÓN | M26: RE-031 | N26: =VLOOKUP(Tabla2[[#This Row],[No. ECO]],Hoja1!A:D,2,FALSE) -> BMW- | O26: SI | P26: 45572 | Q26: Salinas | T26: Etiquetas de fila | U26: Cuenta de MARCA TRACTO
A27: =Tabla2[[#This Row],[TIPO2]]&" "&Tabla2[[#This Row],[ESTRUCTURA]] -> QUINTA BAJA COTTRELL | B27: TLEA-037 | C27: 3BKZL40X9PF536269 | D27: KENWORTH | E27: CUMMINS X15 | F27: X15 | G27: T880 | H27: 2023 | I27: COTTRELL | J27: QUINTA BAJA | K27: QB | L27: RENOVACIÓN | M27: RE-037 | N27: =VLOOKUP(Tabla2[[#This Row],[No. ECO]],Hoja1!A:D,2,FALSE) -> GM- | O27: NO | T27: KENWORTH | U27: 160
A28: =Tabla2[[#This Row],[TIPO2]]&" "&Tabla2[[#This Row],[ESTRUCTURA]] -> QUINTA BAJA COTTRELL | B28: TLEA-038 | C28: 3BKZL40X7PF536268 | D28: KENWORTH | E28: CUMMINS X15 | F28: X15 | G28: T880 | H28: 2023 | I28: COTTRELL | J28: QUINTA BAJA | K28: QB | L28: RENOVACIÓN | M28: RE-038 | N28: =VLOOKUP(Tabla2[[#This Row],[No. ECO]],Hoja1!A:D,2,FALSE) -> GM- | O28: SI | P28: 45588 | Q28: Salinas | T28: WESTERN STAR | U28: 45
A29: =Tabla2[[#This Row],[TIPO2]]&" "&Tabla2[[#This Row],[ESTRUCTURA]] -> SEMI FULL DOLLY COTTRELL | B29: TLEA-041 | C29: 3BKZL40X9RF540180 | D29: KENWORTH | E29: CUMMINS X15 | F29: X15 | G29: T880 | H29: 2024 | I29: COTTRELL | J29: SEMI FULL DOLLY | K29: DOLLY | L29: RENOVACIÓN | M29: RE-041 | N29: =VLOOKUP(Tabla2[[#This Row],[No. ECO]],Hoja1!A:D,2,FALSE) -> BMW- | O29: SI | P29: 45610 | Q29: Salinas | T29: INTERNATIONAL | U29: 9
A30: =Tabla2[[#This Row],[TIPO2]]&" "&Tabla2[[#This Row],[ESTRUCTURA]] -> SEMI FULL DOLLY COTTRELL | B30: TLEA-042 | C30: 3BKZL40X0RF540181 | D30: KENWORTH | E30: CUMMINS X15 | F30: X15 | G30: T880 | H30: 2024 | I30: COTTRELL | J30: SEMI FULL DOLLY | K30: DOLLY | L30: RENOVACIÓN | M30: RE-042 | N30: =VLOOKUP(Tabla2[[#This Row],[No. ECO]],Hoja1!A:D,2,FALSE) -> BMW- | O30: SI | P30: 45572 | Q30: Salinas | T30: FREIGHLINER | U30: 1
A31: =Tabla2[[#This Row],[TIPO2]]&" "&Tabla2[[#This Row],[ESTRUCTURA]] -> SEMI FULL DOLLY COTTRELL | B31: TLEA-043 | C31: 3BKALPX2GF866451 | D31: KENWORTH | E31: CUMMINS X15 | F31: X15 | G31: T660 | H31: 2024 | I31: COTTRELL | J31: SEMI FULL DOLLY | K31: DOLLY | L31: RENOVACIÓN | M31: RE-043 | N31: =VLOOKUP(Tabla2[[#This Row],[No. ECO]],Hoja1!A:D,2,FALSE) -> GM- | O31: NO | T31: Total general | U31: 215
A32: =Tabla2[[#This Row],[TIPO2]]&" "&Tabla2[[#This Row],[ESTRUCTURA]] -> SEMI FULL DOLLY COTTRELL | B32: TLEA-044 | C32: 3BKZL40X5RF538068 | D32: KENWORTH | E32: CUMMINS X15 | F32: X15 | G32: T880 | H32: 2024 | I32: COTTRELL | J32: SEMI FULL DOLLY | K32: DOLLY | L32: RENOVACIÓN | M32: RE-044 | N32: =VLOOKUP(Tabla2[[#This Row],[No. ECO]],Hoja1!A:D,2,FALSE) -> GM- | O32: NO
A33: =Tabla2[[#This Row],[TIPO2]]&" "&Tabla2[[#This Row],[ESTRUCTURA]] -> SEMI FULL DOLLY COTTRELL | B33: TLEA-046 | C33: 3BKALP9X1GF866442 | D33: KENWORTH | E33: PACCAR MX-13 | F33: MX-13 | G33: T660 | H33: 2016 | I33: COTTRELL | J33: SEMI FULL DOLLY | K33: DOLLY | L33: VIEJA | M33: RE-046 | N33: =VLOOKUP(Tabla2[[#This Row],[No. ECO]],Hoja1!A:D,2,FALSE) -> MZ- | O33: NO
A34: =Tabla2[[#This Row],[TIPO2]]&" "&Tabla2[[#This Row],[ESTRUCTURA]] -> SEMI FULL DOLLY COTTRELL | B34: TLEA-047 | C34: 3BKALP9X8GF866454 | D34: KENWORTH | E34: PACCAR MX-13 | F34: MX-13 | G34: T660 | H34: 2016 | I34: COTTRELL | J34: SEMI FULL DOLLY | K34: DOLLY | L34: VIEJA | M34: RE-047 | N34: =VLOOKUP(Tabla2[[#This Row],[No. ECO]],Hoja1!A:D,2,FALSE) -> AU- | O34: NO
A35: =Tabla2[[#This Row],[TIPO2]]&" "&Tabla2[[#This Row],[ESTRUCTURA]] -> SEMI FULL DOLLY COTTRELL | B35: TLEA-048 | C35: 3BKALP9X5GF866444 | D35: KENWORTH | E35: PACCAR MX-13 | F35: MX-13 | G35: T660 | H35: 2016 | I35: COTTRELL | J35: SEMI FULL DOLLY | K35: DOLLY | L35: VIEJA | M35: RE-048 | N35: =VLOOKUP(Tabla2[[#This Row],[No. ECO]],Hoja1!A:D,2,FALSE) -> MZ- | O35: NO
A36: =Tabla2[[#This Row],[TIPO2]]&" "&Tabla2[[#This Row],[ESTRUCTURA]] -> SEMI FULL DOLLY COTTRELL | B36: TLEA-049 | C36: 3BKALP9X2GF866448 | D36: KENWORTH | E36: PACCAR MX-13 | F36: MX-13 | G36: T660 | H36: 2016 | I36: COTTRELL | J36: SEMI FULL DOLLY | K36: DOLLY | L36: VIEJA | M36: RE-049 | N36: =VLOOKUP(Tabla2[[#This Row],[No. ECO]],Hoja1!A:D,2,FALSE) -> AU- | O36: NO
A37: =Tabla2[[#This Row],[TIPO2]]&" "&Tabla2[[#This Row],[ESTRUCTURA]] -> SEMI FULL DOLLY COTTRELL | B37: TLEA-050 | C37: 3BKZL40X7RF538069 | D37: KENWORTH | E37: CUMMINS X15 | F37: X15 | G37: T880 | H37: 2024 | I37: COTTRELL | J37: SEMI FULL DOLLY | K37: DOLLY | L37: RENOVACIÓN | M37: RE-050 | N37: =VLOOKUP(Tabla2[[#This Row],[No. ECO]],Hoja1!A:D,2,FALSE) -> GM- | O37: SI | P37: 45572 | Q37: Salinas
A38: =Tabla2[[#This Row],[TIPO2]]&" "&Tabla2[[#This Row],[ESTRUCTURA]] -> SEMI FULL DOLLY COTTRELL | B38: TLEA-054 | C38: 3BKALP9X7GF866459 | D38: KENWORTH | E38: PACCAR MX-13 | F38: MX-13 | G38: T660 | H38: 2016 | I38: COTTRELL | J38: SEMI FULL DOLLY | K38: DOLLY | L38: VIEJA | M38: RE-054 | N38: =VLOOKUP(Tabla2[[#This Row],[No. ECO]],Hoja1!A:D,2,FALSE) -> MZ- | O38: NO
A39: =Tabla2[[#This Row],[TIPO2]]&" "&Tabla2[[#This Row],[ESTRUCTURA]] -> SEMI FULL DOLLY COTTRELL | B39: TLEA-055 | C39: 3BKALP9X5GF866461 | D39: KENWORTH | E39: PACCAR MX-13 | F39: MX-13 | G39: T660 | H39: 2016 | I39: COTTRELL | J39: SEMI FULL DOLLY | K39: DOLLY | L39: VIEJA | M39: RE-055 | N39: =VLOOKUP(Tabla2[[#This Row],[No. ECO]],Hoja1!A:D,2,FALSE) -> TY-T- | O39: NO
A40: =Tabla2[[#This Row],[TIPO2]]&" "&Tabla2[[#This Row],[ESTRUCTURA]] -> SEMI FULL DOLLY COTTRELL | B40: TLEA-057 | C40: 3BKZL40X9RF540177 | D40: KENWORTH | E40: CUMMINS X15 | F40: X15 | G40: T880 | H40: 2024 | I40: COTTRELL | J40: SEMI FULL DOLLY | K40: DOLLY | L40: RENOVACIÓN | M40: RE-057 | N40: =VLOOKUP(Tabla2[[#This Row],[No. ECO]],Hoja1!A:D,2,FALSE) -> GM- | O40: SI | P40: 45525 | Q40: Salamanca
...

Sheet Hoja2
A1: traC-to | B1: gober | D1: feC-ha
A2: C-01 | B2: NO | C2: 0 | D2: null | F2: =CONCATENATE("update unidad set gobernada = ", C2,", fechagobernada = ",D2,"' where name = '",A2,"';") -> update unidad set gobernada = 0, fechagobernada = null' where name = 'C-01';
A3: C-02 | B3: SI | C3: 1 | D3: '2024-08-01 | F3: =CONCATENATE("update unidad set gobernada = ", C3,", fechagobernada = ",D3,"' where name = '",A3,"';") -> update unidad set gobernada = 1, fechagobernada = '2024-08-01' where name = 'C-02';
A4: C-03 | B4: SI | C4: 1 | D4: '2024-08-17 | F4: =CONCATENATE("update unidad set gobernada = ", C4,", fechagobernada = ",D4,"' where name = '",A4,"';") -> update unidad set gobernada = 1, fechagobernada = '2024-08-17' where name = 'C-03';
A5: C-04 | B5: SI | C5: 1 | D5: '2024-10-07 | F5: =CONCATENATE("update unidad set gobernada = ", C5,", fechagobernada = ",D5,"' where name = '",A5,"';") -> update unidad set gobernada = 1, fechagobernada = '2024-10-07' where name = 'C-04';
A6: C-36 | B6: NO | C6: 0 | D6: null | F6: =CONCATENATE("update unidad set gobernada = ", C6,", fechagobernada = ",D6,"' where name = '",A6,"';") -> update unidad set gobernada = 0, fechagobernada = null' where name = 'C-36';
A7: C-37 | B7: SI | C7: 1 | D7: '2024-08-17 | F7: =CONCATENATE("update unidad set gobernada = ", C7,", fechagobernada = ",D7,"' where name = '",A7,"';") -> update unidad set gobernada = 1, fechagobernada = '2024-08-17' where name = 'C-37';
A8: C-38 | B8: SI | C8: 1 | D8: '2024-08-01 | F8: =CONCATENATE("update unidad set gobernada = ", C8,", fechagobernada = ",D8,"' where name = '",A8,"';") -> update unidad set gobernada = 1, fechagobernada = '2024-08-01' where name = 'C-38';
A9: C-39 | B9: SI | C9: 1 | D9: '2024-10-31 | F9: =CONCATENATE("update unidad set gobernada = ", C9,", fechagobernada = ",D9,"' where name = '",A9,"';") -> update unidad set gobernada = 1, fechagobernada = '2024-10-31' where name = 'C-39';
A10: C-40 | B10: SI | C10: 1 | D10: '2024-09-20 | F10: =CONCATENATE("update unidad set gobernada = ", C10,", fechagobernada = ",D10,"' where name = '",A10,"';") -> update unidad set gobernada = 1, fechagobernada = '2024-09-20' where name = 'C-40';
A11: C-41 | B11: SI | C11: 1 | D11: '2024-08-17 | F11: =CONCATENATE("update unidad set gobernada = ", C11,", fechagobernada = ",D11,"' where name = '",A11,"';") -> update unidad set gobernada = 1, fechagobernada = '2024-08-17' where name = 'C-41';
A12: C-42 | B12: NO | C12: 0 | D12: null | F12: =CONCATENATE("update unidad set gobernada = ", C12,", fechagobernada = ",D12,"' where name = '",A12,"';") -> update unidad set gobernada = 0, fechagobernada = null' where name = 'C-42';
A13: C-43 | B13: NO | C13: 0 | D13: null | F13: =CONCATENATE("update unidad set gobernada = ", C13,", fechagobernada = ",D13,"' where name = '",A13,"';") -> update unidad set gobernada = 0, fechagobernada = null' where name = 'C-43';
... A292: TLEA-368 | B292: SI | C292: 1 | D292: '2024-11-19 | F292: =CONCATENATE("update unidad set gobernada = ", C292,", fechagobernada = ",D292,"' where name = '",A292,"';") -> update unidad set gobernada = 1, fechagobernada = '2024-11-19' where name = 'TLEA-368';

Sheet Hoja3
A1: Unidad | B1: PROVEEDOR | C1: INSTALADO
A2: TLEA-016 | B2: COFRIMEX | C2: OK
A3: TLEA-022 | B3: ADESU | C3: OK
A4: TLEA-025 | B4: ADESU | C4: OK
A5: TLEA-030 | B5: ADESU | C5: OK
A6: TLEA-043 | B6: ADESU | C6: OK
A7: TLEA-044 | B7: ADESU | C7: OK
A8: TLEA-051 | B8: COFRIMEX | C8: OK
A9: TLEA-057 | B9: ADESU | C9: OK
A10: TLEA-064 | B10: VIESA | C10: OK
A11: TLEA-065 | B11: ADESU | C11: OK
A12: TLEA-066 | B12: ADESU | C12: OK
... A76: TLEA-307 | B76: ADESU | C76: OK

Sheet Hoja1
A1: UNIDAD | B1: CLIENTE | C1: UN NEGOCIO | D1: DIVISION | E1: DIVISION
A2: C01 | B2: TY-APASEO- | C2: U5 | D2: D3 | E2: =VLOOKUP(A2,'BD Parametros'!B:M,12,FALSE) -> RE-C01
A3: C02 | B3: TY-APASEO- | C3: U5 | D3: D3 | E3: =VLOOKUP(A3,'BD Parametros'!B:M,12,FALSE) -> RE-C02
A4: C03 | B4: DT- | C4: U3 | D4: D2 | E4: =VLOOKUP(A4,'BD Parametros'!B:M,12,FALSE) -> RE-C03
A5: C04 | B5: DT- | C5: U3 | D5: D2 | E5: =VLOOKUP(A5,'BD Parametros'!B:M,12,FALSE) -> RE-C04
A6: C36 | B6: TY-APASEO- | C6: U5 | D6: D3 | E6: =VLOOKUP(A6,'BD Parametros'!B:M,12,FALSE) -> RE-C36
A7: C37 | B7: DT- | C7: U3 | D7: D2 | E7: =VLOOKUP(A7,'BD Parametros'!B:M,12,FALSE) -> RE-C37
A8: C38 | B8: TY-APASEO- | C8: U5 | D8: D3 | E8: =VLOOKUP(A8,'BD Parametros'!B:M,12,FALSE) -> RE-C38
A9: C39 | B9: TY-APASEO- | C9: U5 | D9: D3 | E9: =VLOOKUP(A9,'BD Parametros'!B:M,12,FALSE) -> RE-C39
A10: C40 | B10: DT- | C10: U3 | D10: D2 | E10: =VLOOKUP(A10,'BD Parametros'!B:M,12,FALSE) -> RE-C40
A11: C41 | B11: DT- | C11: U3 | D11: D2 | E11: =VLOOKUP(A11,'BD Parametros'!B:M,12,FALSE) -> RE-C41
A12: C42 | B12: DT- | C12: U3 | D12: D2 | E12: =VLOOKUP(A12,'BD Parametros'!B:M,12,FALSE) -> RE-C42
A13: C43 | B13: DT- | C13: U3 | D13: D2 | E13: =VLOOKUP(A13,'BD Parametros'!B:M,12,FALSE) -> RE-C45
... A281: TLEA-352 | B281: DT- | C281: U3 | D281: D2 | E281: =VLOOKUP(A281,'BD Parametros'!B:M,12,FALSE) -> RE-C05

Sheet GRAFICO_UNID

Sheet ESTRUCTURAS
A1: PROVEEDOR | B1: MODELO
A2: Cottrell | B2: Quinta Baja
A3: Cottrell | B3: Quinta Baja 2.0
A4: Cottrell | B4: Dolly
A5: Cottrell | B5: Full
A6: Cottrell | B6: Quinta Baja Western
A7: Lohr | B7: Full
A8: Boydstun | B8: Quinta Baja Western
A9: Boydstun | B9: Quinta Alta
A10: Jaes | B10: Quinta Baja
